2025-03-23 21:45:49,875 INFO: Permissions and roles initialized successfully. [in /Users/mcc/Documents/Develop/backup/sgha/backend/models/user.py:139]
2025-03-23 21:45:49,878 INFO: Permisos y roles inicializados correctamente [in /Users/mcc/Documents/Develop/backup/sgha/backend/app.py:57]
2025-03-23 21:54:06,515 WARNING: Intento de acceso con token inválido: Signature verification failed [in /Users/mcc/Documents/Develop/backup/sgha/backend/app.py:65]
2025-03-23 21:54:06,524 WARNING: Intento de acceso con token inválido: Signature verification failed [in /Users/mcc/Documents/Develop/backup/sgha/backend/app.py:65]
2025-03-23 21:57:56,118 ERROR: Exception on /suppliers/ [POST] [in /Users/mcc/.virtualenvs/sgha/lib/python3.12/site-packages/flask/app.py:875]
Traceback (most recent call last):
  File "/Users/mcc/.virtualenvs/sgha/lib/python3.12/site-packages/flask/app.py", line 1511, in wsgi_app
    response = self.full_dispatch_request()
               ^^^^^^^^^^^^^^^^^^^^^^^^^^^^
  File "/Users/mcc/.virtualenvs/sgha/lib/python3.12/site-packages/flask/app.py", line 919, in full_dispatch_request
    rv = self.handle_user_exception(e)
         ^^^^^^^^^^^^^^^^^^^^^^^^^^^^^
  File "/Users/mcc/.virtualenvs/sgha/lib/python3.12/site-packages/flask_cors/extension.py", line 176, in wrapped_function
    return cors_after_request(app.make_response(f(*args, **kwargs)))
                                                ^^^^^^^^^^^^^^^^^^
  File "/Users/mcc/.virtualenvs/sgha/lib/python3.12/site-packages/flask/app.py", line 917, in full_dispatch_request
    rv = self.dispatch_request()
         ^^^^^^^^^^^^^^^^^^^^^^^
  File "/Users/mcc/.virtualenvs/sgha/lib/python3.12/site-packages/flask/app.py", line 902, in dispatch_request
    return self.ensure_sync(self.view_functions[rule.endpoint])(**view_args)  # type: ignore[no-any-return]
           ^^^^^^^^^^^^^^^^^^^^^^^^^^^^^^^^^^^^^^^^^^^^^^^^^^^^^^^^^^^^^^^^^
  File "/Users/mcc/.virtualenvs/sgha/lib/python3.12/site-packages/flask_jwt_extended/view_decorators.py", line 170, in decorator
    return current_app.ensure_sync(fn)(*args, **kwargs)
           ^^^^^^^^^^^^^^^^^^^^^^^^^^^^^^^^^^^^^^^^^^^^
  File "/Users/mcc/Documents/Develop/backup/sgha/backend/routes/supplier_routes.py", line 23, in create_supplier
    supplier = Supplier(**data)
               ^^^^^^^^^^^^^^^^
TypeError: models.supplier.Supplier() argument after ** must be a mapping, not list
2025-03-23 22:02:37,501 ERROR: Exception on /suppliers/ [POST] [in /Users/mcc/.virtualenvs/sgha/lib/python3.12/site-packages/flask/app.py:875]
Traceback (most recent call last):
  File "/Users/mcc/.virtualenvs/sgha/lib/python3.12/site-packages/flask/app.py", line 1511, in wsgi_app
    response = self.full_dispatch_request()
               ^^^^^^^^^^^^^^^^^^^^^^^^^^^^
  File "/Users/mcc/.virtualenvs/sgha/lib/python3.12/site-packages/flask/app.py", line 919, in full_dispatch_request
    rv = self.handle_user_exception(e)
         ^^^^^^^^^^^^^^^^^^^^^^^^^^^^^
  File "/Users/mcc/.virtualenvs/sgha/lib/python3.12/site-packages/flask_cors/extension.py", line 176, in wrapped_function
    return cors_after_request(app.make_response(f(*args, **kwargs)))
                                                ^^^^^^^^^^^^^^^^^^
  File "/Users/mcc/.virtualenvs/sgha/lib/python3.12/site-packages/flask/app.py", line 917, in full_dispatch_request
    rv = self.dispatch_request()
         ^^^^^^^^^^^^^^^^^^^^^^^
  File "/Users/mcc/.virtualenvs/sgha/lib/python3.12/site-packages/flask/app.py", line 902, in dispatch_request
    return self.ensure_sync(self.view_functions[rule.endpoint])(**view_args)  # type: ignore[no-any-return]
           ^^^^^^^^^^^^^^^^^^^^^^^^^^^^^^^^^^^^^^^^^^^^^^^^^^^^^^^^^^^^^^^^^
  File "/Users/mcc/.virtualenvs/sgha/lib/python3.12/site-packages/flask_jwt_extended/view_decorators.py", line 170, in decorator
    return current_app.ensure_sync(fn)(*args, **kwargs)
           ^^^^^^^^^^^^^^^^^^^^^^^^^^^^^^^^^^^^^^^^^^^^
  File "/Users/mcc/Documents/Develop/backup/sgha/backend/routes/supplier_routes.py", line 23, in create_supplier
    supplier = Supplier(**data)
               ^^^^^^^^^^^^^^^^
TypeError: models.supplier.Supplier() argument after ** must be a mapping, not list
2025-03-23 22:05:27,353 ERROR: Exception on /suppliers/ [POST] [in /Users/mcc/.virtualenvs/sgha/lib/python3.12/site-packages/flask/app.py:875]
Traceback (most recent call last):
  File "/Users/mcc/.virtualenvs/sgha/lib/python3.12/site-packages/flask/app.py", line 1511, in wsgi_app
    response = self.full_dispatch_request()
               ^^^^^^^^^^^^^^^^^^^^^^^^^^^^
  File "/Users/mcc/.virtualenvs/sgha/lib/python3.12/site-packages/flask/app.py", line 919, in full_dispatch_request
    rv = self.handle_user_exception(e)
         ^^^^^^^^^^^^^^^^^^^^^^^^^^^^^
  File "/Users/mcc/.virtualenvs/sgha/lib/python3.12/site-packages/flask_cors/extension.py", line 176, in wrapped_function
    return cors_after_request(app.make_response(f(*args, **kwargs)))
                                                ^^^^^^^^^^^^^^^^^^
  File "/Users/mcc/.virtualenvs/sgha/lib/python3.12/site-packages/flask/app.py", line 917, in full_dispatch_request
    rv = self.dispatch_request()
         ^^^^^^^^^^^^^^^^^^^^^^^
  File "/Users/mcc/.virtualenvs/sgha/lib/python3.12/site-packages/flask/app.py", line 902, in dispatch_request
    return self.ensure_sync(self.view_functions[rule.endpoint])(**view_args)  # type: ignore[no-any-return]
           ^^^^^^^^^^^^^^^^^^^^^^^^^^^^^^^^^^^^^^^^^^^^^^^^^^^^^^^^^^^^^^^^^
  File "/Users/mcc/.virtualenvs/sgha/lib/python3.12/site-packages/flask_jwt_extended/view_decorators.py", line 170, in decorator
    return current_app.ensure_sync(fn)(*args, **kwargs)
           ^^^^^^^^^^^^^^^^^^^^^^^^^^^^^^^^^^^^^^^^^^^^
  File "/Users/mcc/Documents/Develop/backup/sgha/backend/routes/supplier_routes.py", line 23, in create_supplier
TypeError: models.supplier.Supplier() argument after ** must be a mapping, not list
2025-03-23 22:20:15,407 ERROR: Exception on /suppliers/ [POST] [in /Users/mcc/.virtualenvs/sgha/lib/python3.12/site-packages/flask/app.py:875]
Traceback (most recent call last):
  File "/Users/mcc/.virtualenvs/sgha/lib/python3.12/site-packages/flask/app.py", line 1511, in wsgi_app
    response = self.full_dispatch_request()
               ^^^^^^^^^^^^^^^^^^^^^^^^^^^^
  File "/Users/mcc/.virtualenvs/sgha/lib/python3.12/site-packages/flask/app.py", line 919, in full_dispatch_request
    rv = self.handle_user_exception(e)
         ^^^^^^^^^^^^^^^^^^^^^^^^^^^^^
  File "/Users/mcc/.virtualenvs/sgha/lib/python3.12/site-packages/flask_cors/extension.py", line 176, in wrapped_function
    return cors_after_request(app.make_response(f(*args, **kwargs)))
                                                ^^^^^^^^^^^^^^^^^^
  File "/Users/mcc/.virtualenvs/sgha/lib/python3.12/site-packages/flask/app.py", line 917, in full_dispatch_request
    rv = self.dispatch_request()
         ^^^^^^^^^^^^^^^^^^^^^^^
  File "/Users/mcc/.virtualenvs/sgha/lib/python3.12/site-packages/flask/app.py", line 902, in dispatch_request
    return self.ensure_sync(self.view_functions[rule.endpoint])(**view_args)  # type: ignore[no-any-return]
           ^^^^^^^^^^^^^^^^^^^^^^^^^^^^^^^^^^^^^^^^^^^^^^^^^^^^^^^^^^^^^^^^^
  File "/Users/mcc/.virtualenvs/sgha/lib/python3.12/site-packages/flask_jwt_extended/view_decorators.py", line 170, in decorator
    return current_app.ensure_sync(fn)(*args, **kwargs)
           ^^^^^^^^^^^^^^^^^^^^^^^^^^^^^^^^^^^^^^^^^^^^
  File "/Users/mcc/Documents/Develop/backup/sgha/backend/routes/supplier_routes.py", line 23, in create_supplier
    return jsonify({'message': 'Invalid JSON format'}), 400
           ^^^^^^^^^^^^^^^^
TypeError: models.supplier.Supplier() argument after ** must be a mapping, not list
2025-03-23 22:20:25,683 INFO: Inicio de la aplicación [in /Users/mcc/Documents/Develop/backup/sgha/backend/app.py:42]
2025-03-23 22:20:25,840 INFO: Permissions and roles initialized successfully. [in /Users/mcc/Documents/Develop/backup/sgha/backend/models/user.py:139]
2025-03-23 22:20:25,841 INFO: Permisos y roles inicializados correctamente [in /Users/mcc/Documents/Develop/backup/sgha/backend/app.py:57]
2025-03-23 22:20:31,708 WARNING: Intento de acceso con token inválido: Signature verification failed [in /Users/mcc/Documents/Develop/backup/sgha/backend/app.py:65]
2025-03-23 22:20:31,712 WARNING: Intento de acceso con token inválido: Signature verification failed [in /Users/mcc/Documents/Develop/backup/sgha/backend/app.py:65]
