2025-03-18 11:48:19,444 ERROR: Exception on /auth/register [POST] [in /Users/mcc/.virtualenvs/sgha/lib/python3.12/site-packages/flask/app.py:875]
Traceback (most recent call last):
  File "/Users/mcc/.virtualenvs/sgha/lib/python3.12/site-packages/sqlalchemy/engine/base.py", line 1964, in _exec_single_context
    self.dialect.do_execute(
  File "/Users/mcc/.virtualenvs/sgha/lib/python3.12/site-packages/sqlalchemy/engine/default.py", line 942, in do_execute
    cursor.execute(statement, parameters)
psycopg2.errors.NotNullViolation: null value in column "username" of relation "user" violates not-null constraint
DETAIL:  Failing row contains (6, null, testuser@example.com, scrypt:32768:8:1$yctZFIMvblOBdsMj$e290255d4796830419450fd9fe3598..., 2, t, null, null, null, null, null, null, 2025-03-18 10:48:19.443182, 2025-03-18 10:48:19.443187, null, 0, null, null, null).


The above exception was the direct cause of the following exception:

Traceback (most recent call last):
  File "/Users/mcc/.virtualenvs/sgha/lib/python3.12/site-packages/flask/app.py", line 1511, in wsgi_app
    response = self.full_dispatch_request()
               ^^^^^^^^^^^^^^^^^^^^^^^^^^^^
  File "/Users/mcc/.virtualenvs/sgha/lib/python3.12/site-packages/flask/app.py", line 919, in full_dispatch_request
    rv = self.handle_user_exception(e)
         ^^^^^^^^^^^^^^^^^^^^^^^^^^^^^
  File "/Users/mcc/.virtualenvs/sgha/lib/python3.12/site-packages/flask_cors/extension.py", line 176, in wrapped_function
    return cors_after_request(app.make_response(f(*args, **kwargs)))
                                                ^^^^^^^^^^^^^^^^^^
  File "/Users/mcc/.virtualenvs/sgha/lib/python3.12/site-packages/flask/app.py", line 917, in full_dispatch_request
    rv = self.dispatch_request()
         ^^^^^^^^^^^^^^^^^^^^^^^
  File "/Users/mcc/.virtualenvs/sgha/lib/python3.12/site-packages/flask/app.py", line 902, in dispatch_request
    return self.ensure_sync(self.view_functions[rule.endpoint])(**view_args)  # type: ignore[no-any-return]
           ^^^^^^^^^^^^^^^^^^^^^^^^^^^^^^^^^^^^^^^^^^^^^^^^^^^^^^^^^^^^^^^^^
  File "/Users/mcc/Documents/Develop/backup/sgha/backend/routes/auth.py", line 61, in register
    db.session.commit()
  File "/Users/mcc/.virtualenvs/sgha/lib/python3.12/site-packages/sqlalchemy/orm/scoping.py", line 599, in commit
    return self._proxied.commit()
           ^^^^^^^^^^^^^^^^^^^^^^
  File "/Users/mcc/.virtualenvs/sgha/lib/python3.12/site-packages/sqlalchemy/orm/session.py", line 2032, in commit
    trans.commit(_to_root=True)
  File "<string>", line 2, in commit
  File "/Users/mcc/.virtualenvs/sgha/lib/python3.12/site-packages/sqlalchemy/orm/state_changes.py", line 139, in _go
    ret_value = fn(self, *arg, **kw)
                ^^^^^^^^^^^^^^^^^^^^
  File "/Users/mcc/.virtualenvs/sgha/lib/python3.12/site-packages/sqlalchemy/orm/session.py", line 1313, in commit
    self._prepare_impl()
  File "<string>", line 2, in _prepare_impl
  File "/Users/mcc/.virtualenvs/sgha/lib/python3.12/site-packages/sqlalchemy/orm/state_changes.py", line 139, in _go
    ret_value = fn(self, *arg, **kw)
                ^^^^^^^^^^^^^^^^^^^^
  File "/Users/mcc/.virtualenvs/sgha/lib/python3.12/site-packages/sqlalchemy/orm/session.py", line 1288, in _prepare_impl
    self.session.flush()
  File "/Users/mcc/.virtualenvs/sgha/lib/python3.12/site-packages/sqlalchemy/orm/session.py", line 4353, in flush
    self._flush(objects)
  File "/Users/mcc/.virtualenvs/sgha/lib/python3.12/site-packages/sqlalchemy/orm/session.py", line 4488, in _flush
    with util.safe_reraise():
  File "/Users/mcc/.virtualenvs/sgha/lib/python3.12/site-packages/sqlalchemy/util/langhelpers.py", line 146, in __exit__
    raise exc_value.with_traceback(exc_tb)
  File "/Users/mcc/.virtualenvs/sgha/lib/python3.12/site-packages/sqlalchemy/orm/session.py", line 4449, in _flush
    flush_context.execute()
  File "/Users/mcc/.virtualenvs/sgha/lib/python3.12/site-packages/sqlalchemy/orm/unitofwork.py", line 466, in execute
    rec.execute(self)
  File "/Users/mcc/.virtualenvs/sgha/lib/python3.12/site-packages/sqlalchemy/orm/unitofwork.py", line 642, in execute
    util.preloaded.orm_persistence.save_obj(
  File "/Users/mcc/.virtualenvs/sgha/lib/python3.12/site-packages/sqlalchemy/orm/persistence.py", line 93, in save_obj
    _emit_insert_statements(
  File "/Users/mcc/.virtualenvs/sgha/lib/python3.12/site-packages/sqlalchemy/orm/persistence.py", line 1233, in _emit_insert_statements
    result = connection.execute(
             ^^^^^^^^^^^^^^^^^^^
  File "/Users/mcc/.virtualenvs/sgha/lib/python3.12/site-packages/sqlalchemy/engine/base.py", line 1416, in execute
    return meth(
           ^^^^^
  File "/Users/mcc/.virtualenvs/sgha/lib/python3.12/site-packages/sqlalchemy/sql/elements.py", line 523, in _execute_on_connection
    return connection._execute_clauseelement(
           ^^^^^^^^^^^^^^^^^^^^^^^^^^^^^^^^^^
  File "/Users/mcc/.virtualenvs/sgha/lib/python3.12/site-packages/sqlalchemy/engine/base.py", line 1638, in _execute_clauseelement
    ret = self._execute_context(
          ^^^^^^^^^^^^^^^^^^^^^^
  File "/Users/mcc/.virtualenvs/sgha/lib/python3.12/site-packages/sqlalchemy/engine/base.py", line 1843, in _execute_context
    return self._exec_single_context(
           ^^^^^^^^^^^^^^^^^^^^^^^^^^
  File "/Users/mcc/.virtualenvs/sgha/lib/python3.12/site-packages/sqlalchemy/engine/base.py", line 1983, in _exec_single_context
    self._handle_dbapi_exception(
  File "/Users/mcc/.virtualenvs/sgha/lib/python3.12/site-packages/sqlalchemy/engine/base.py", line 2352, in _handle_dbapi_exception
    raise sqlalchemy_exception.with_traceback(exc_info[2]) from e
  File "/Users/mcc/.virtualenvs/sgha/lib/python3.12/site-packages/sqlalchemy/engine/base.py", line 1964, in _exec_single_context
    self.dialect.do_execute(
  File "/Users/mcc/.virtualenvs/sgha/lib/python3.12/site-packages/sqlalchemy/engine/default.py", line 942, in do_execute
    cursor.execute(statement, parameters)
sqlalchemy.exc.IntegrityError: (psycopg2.errors.NotNullViolation) null value in column "username" of relation "user" violates not-null constraint
DETAIL:  Failing row contains (6, null, testuser@example.com, scrypt:32768:8:1$yctZFIMvblOBdsMj$e290255d4796830419450fd9fe3598..., 2, t, null, null, null, null, null, null, 2025-03-18 10:48:19.443182, 2025-03-18 10:48:19.443187, null, 0, null, null, null).

[SQL: INSERT INTO "user" (username, email, password_hash, role_id, is_active, name, second_name, last_name, phone_number, created_at, updated_at, last_login, login_attempts, locked_until) VALUES (%(username)s, %(email)s, %(password_hash)s, %(role_id)s, %(is_active)s, %(name)s, %(second_name)s, %(last_name)s, %(phone_number)s, %(created_at)s, %(updated_at)s, %(last_login)s, %(login_attempts)s, %(locked_until)s) RETURNING "user".id]
[parameters: {'username': None, 'email': 'testuser@example.com', 'password_hash': 'scrypt:32768:8:1$yctZFIMvblOBdsMj$e290255d4796830419450fd9fe3598dfdedeaf69b1234ba9eb498fd7d0de82314d624102a6986ab62b619bfe02234829f2845517ae331702773cc18767275a18', 'role_id': 2, 'is_active': True, 'name': None, 'second_name': None, 'last_name': None, 'phone_number': None, 'created_at': datetime.datetime(2025, 3, 18, 10, 48, 19, 443182), 'updated_at': datetime.datetime(2025, 3, 18, 10, 48, 19, 443187), 'last_login': None, 'login_attempts': 0, 'locked_until': None}]
(Background on this error at: https://sqlalche.me/e/20/gkpj)
2025-03-18 11:48:34,116 INFO: Inicio de la aplicaci√≥n [in /Users/mcc/Documents/Develop/backup/sgha/backend/app.py:38]
2025-03-18 11:48:34,272 INFO: Permissions and roles initialized successfully. [in /Users/mcc/Documents/Develop/backup/sgha/backend/models/user.py:139]
2025-03-18 11:48:34,273 INFO: Permisos y roles inicializados correctamente [in /Users/mcc/Documents/Develop/backup/sgha/backend/app.py:53]
