2025-03-18 12:18:12,176 ERROR: Exception on /users/ [GET] [in /Users/mcc/.virtualenvs/sgha/lib/python3.12/site-packages/flask/app.py:875]
Traceback (most recent call last):
  File "/Users/mcc/.virtualenvs/sgha/lib/python3.12/site-packages/flask/app.py", line 1511, in wsgi_app
    response = self.full_dispatch_request()
               ^^^^^^^^^^^^^^^^^^^^^^^^^^^^
  File "/Users/mcc/.virtualenvs/sgha/lib/python3.12/site-packages/flask/app.py", line 919, in full_dispatch_request
    rv = self.handle_user_exception(e)
         ^^^^^^^^^^^^^^^^^^^^^^^^^^^^^
  File "/Users/mcc/.virtualenvs/sgha/lib/python3.12/site-packages/flask_cors/extension.py", line 176, in wrapped_function
    return cors_after_request(app.make_response(f(*args, **kwargs)))
                                                ^^^^^^^^^^^^^^^^^^
  File "/Users/mcc/.virtualenvs/sgha/lib/python3.12/site-packages/flask/app.py", line 917, in full_dispatch_request
    rv = self.dispatch_request()
         ^^^^^^^^^^^^^^^^^^^^^^^
  File "/Users/mcc/.virtualenvs/sgha/lib/python3.12/site-packages/flask/app.py", line 902, in dispatch_request
    return self.ensure_sync(self.view_functions[rule.endpoint])(**view_args)  # type: ignore[no-any-return]
           ^^^^^^^^^^^^^^^^^^^^^^^^^^^^^^^^^^^^^^^^^^^^^^^^^^^^^^^^^^^^^^^^^
  File "/Users/mcc/.virtualenvs/sgha/lib/python3.12/site-packages/flask_jwt_extended/view_decorators.py", line 170, in decorator
    return current_app.ensure_sync(fn)(*args, **kwargs)
           ^^^^^^^^^^^^^^^^^^^^^^^^^^^^^^^^^^^^^^^^^^^^
  File "/Users/mcc/Documents/Develop/backup/sgha/backend/utils/decorators.py", line 12, in wrapper
    if not g.current_user:
           ^^^^^^^^^^^^^^
  File "/Users/mcc/.virtualenvs/sgha/lib/python3.12/site-packages/flask/ctx.py", line 56, in __getattr__
    raise AttributeError(name) from None
AttributeError: current_user
2025-03-18 12:18:29,370 WARNING: Intento de acceso con token inválido: Invalid crypto padding [in /Users/mcc/Documents/Develop/backup/sgha/backend/app.py:61]
2025-03-18 12:19:01,475 ERROR: Exception on /users/ [GET] [in /Users/mcc/.virtualenvs/sgha/lib/python3.12/site-packages/flask/app.py:875]
Traceback (most recent call last):
  File "/Users/mcc/.virtualenvs/sgha/lib/python3.12/site-packages/flask/app.py", line 1511, in wsgi_app
    response = self.full_dispatch_request()
               ^^^^^^^^^^^^^^^^^^^^^^^^^^^^
  File "/Users/mcc/.virtualenvs/sgha/lib/python3.12/site-packages/flask/app.py", line 919, in full_dispatch_request
    rv = self.handle_user_exception(e)
         ^^^^^^^^^^^^^^^^^^^^^^^^^^^^^
  File "/Users/mcc/.virtualenvs/sgha/lib/python3.12/site-packages/flask_cors/extension.py", line 176, in wrapped_function
    return cors_after_request(app.make_response(f(*args, **kwargs)))
                                                ^^^^^^^^^^^^^^^^^^
  File "/Users/mcc/.virtualenvs/sgha/lib/python3.12/site-packages/flask/app.py", line 917, in full_dispatch_request
    rv = self.dispatch_request()
         ^^^^^^^^^^^^^^^^^^^^^^^
  File "/Users/mcc/.virtualenvs/sgha/lib/python3.12/site-packages/flask/app.py", line 902, in dispatch_request
    return self.ensure_sync(self.view_functions[rule.endpoint])(**view_args)  # type: ignore[no-any-return]
           ^^^^^^^^^^^^^^^^^^^^^^^^^^^^^^^^^^^^^^^^^^^^^^^^^^^^^^^^^^^^^^^^^
  File "/Users/mcc/.virtualenvs/sgha/lib/python3.12/site-packages/flask_jwt_extended/view_decorators.py", line 170, in decorator
    return current_app.ensure_sync(fn)(*args, **kwargs)
           ^^^^^^^^^^^^^^^^^^^^^^^^^^^^^^^^^^^^^^^^^^^^
  File "/Users/mcc/Documents/Develop/backup/sgha/backend/utils/decorators.py", line 12, in wrapper
    if not g.current_user:
           ^^^^^^^^^^^^^^
  File "/Users/mcc/.virtualenvs/sgha/lib/python3.12/site-packages/flask/ctx.py", line 56, in __getattr__
    raise AttributeError(name) from None
AttributeError: current_user
2025-03-18 12:39:21,780 ERROR: Exception on /users/ [GET] [in /Users/mcc/.virtualenvs/sgha/lib/python3.12/site-packages/flask/app.py:875]
Traceback (most recent call last):
  File "/Users/mcc/.virtualenvs/sgha/lib/python3.12/site-packages/flask/app.py", line 1511, in wsgi_app
    response = self.full_dispatch_request()
               ^^^^^^^^^^^^^^^^^^^^^^^^^^^^
  File "/Users/mcc/.virtualenvs/sgha/lib/python3.12/site-packages/flask/app.py", line 919, in full_dispatch_request
    rv = self.handle_user_exception(e)
         ^^^^^^^^^^^^^^^^^^^^^^^^^^^^^
  File "/Users/mcc/.virtualenvs/sgha/lib/python3.12/site-packages/flask_cors/extension.py", line 176, in wrapped_function
    return cors_after_request(app.make_response(f(*args, **kwargs)))
                                                ^^^^^^^^^^^^^^^^^^
  File "/Users/mcc/.virtualenvs/sgha/lib/python3.12/site-packages/flask/app.py", line 917, in full_dispatch_request
    rv = self.dispatch_request()
         ^^^^^^^^^^^^^^^^^^^^^^^
  File "/Users/mcc/.virtualenvs/sgha/lib/python3.12/site-packages/flask/app.py", line 902, in dispatch_request
    return self.ensure_sync(self.view_functions[rule.endpoint])(**view_args)  # type: ignore[no-any-return]
           ^^^^^^^^^^^^^^^^^^^^^^^^^^^^^^^^^^^^^^^^^^^^^^^^^^^^^^^^^^^^^^^^^
  File "/Users/mcc/.virtualenvs/sgha/lib/python3.12/site-packages/flask_jwt_extended/view_decorators.py", line 170, in decorator
    return current_app.ensure_sync(fn)(*args, **kwargs)
           ^^^^^^^^^^^^^^^^^^^^^^^^^^^^^^^^^^^^^^^^^^^^
  File "/Users/mcc/Documents/Develop/backup/sgha/backend/utils/decorators.py", line 12, in wrapper
    if not g.current_user or not g.current_user.has_permission(permission):
           ^^^^^^^^^^^^^^
  File "/Users/mcc/.virtualenvs/sgha/lib/python3.12/site-packages/flask/ctx.py", line 56, in __getattr__
    raise AttributeError(name) from None
AttributeError: current_user
2025-03-18 12:39:38,111 INFO: Inicio de la aplicación [in /Users/mcc/Documents/Develop/backup/sgha/backend/app.py:38]
2025-03-18 12:39:38,287 INFO: Permissions and roles initialized successfully. [in /Users/mcc/Documents/Develop/backup/sgha/backend/models/user.py:139]
2025-03-18 12:39:38,287 INFO: Permisos y roles inicializados correctamente [in /Users/mcc/Documents/Develop/backup/sgha/backend/app.py:53]
2025-03-18 12:41:41,460 WARNING: Intento de acceso con token inválido: Not enough segments [in /Users/mcc/Documents/Develop/backup/sgha/backend/app.py:61]
