2025-03-16 21:39:53,836 ERROR: Exception on /auth/login [POST] [in /Users/mcc/.virtualenvs/sgha/lib/python3.12/site-packages/flask/app.py:875]
Traceback (most recent call last):
  File "/Users/mcc/.virtualenvs/sgha/lib/python3.12/site-packages/flask/app.py", line 1511, in wsgi_app
    response = self.full_dispatch_request()
               ^^^^^^^^^^^^^^^^^^^^^^^^^^^^
  File "/Users/mcc/.virtualenvs/sgha/lib/python3.12/site-packages/flask/app.py", line 919, in full_dispatch_request
    rv = self.handle_user_exception(e)
         ^^^^^^^^^^^^^^^^^^^^^^^^^^^^^
  File "/Users/mcc/.virtualenvs/sgha/lib/python3.12/site-packages/flask_cors/extension.py", line 176, in wrapped_function
    return cors_after_request(app.make_response(f(*args, **kwargs)))
                                                ^^^^^^^^^^^^^^^^^^
  File "/Users/mcc/.virtualenvs/sgha/lib/python3.12/site-packages/flask/app.py", line 915, in full_dispatch_request
    rv = self.preprocess_request()
         ^^^^^^^^^^^^^^^^^^^^^^^^^
  File "/Users/mcc/.virtualenvs/sgha/lib/python3.12/site-packages/flask/app.py", line 1291, in preprocess_request
    rv = self.ensure_sync(before_func)()
         ^^^^^^^^^^^^^^^^^^^^^^^^^^^^^^^
  File "/Users/mcc/Documents/Develop/backup/sgha/backend/app.py", line 87, in security_middleware
NameError: name 'response' is not defined
2025-03-16 21:39:55,326 ERROR: Exception on /auth/login [POST] [in /Users/mcc/.virtualenvs/sgha/lib/python3.12/site-packages/flask/app.py:875]
Traceback (most recent call last):
  File "/Users/mcc/.virtualenvs/sgha/lib/python3.12/site-packages/flask/app.py", line 1511, in wsgi_app
    response = self.full_dispatch_request()
               ^^^^^^^^^^^^^^^^^^^^^^^^^^^^
  File "/Users/mcc/.virtualenvs/sgha/lib/python3.12/site-packages/flask/app.py", line 919, in full_dispatch_request
    rv = self.handle_user_exception(e)
         ^^^^^^^^^^^^^^^^^^^^^^^^^^^^^
  File "/Users/mcc/.virtualenvs/sgha/lib/python3.12/site-packages/flask_cors/extension.py", line 176, in wrapped_function
    return cors_after_request(app.make_response(f(*args, **kwargs)))
                                                ^^^^^^^^^^^^^^^^^^
  File "/Users/mcc/.virtualenvs/sgha/lib/python3.12/site-packages/flask/app.py", line 915, in full_dispatch_request
    rv = self.preprocess_request()
         ^^^^^^^^^^^^^^^^^^^^^^^^^
  File "/Users/mcc/.virtualenvs/sgha/lib/python3.12/site-packages/flask/app.py", line 1291, in preprocess_request
    rv = self.ensure_sync(before_func)()
         ^^^^^^^^^^^^^^^^^^^^^^^^^^^^^^^
  File "/Users/mcc/Documents/Develop/backup/sgha/backend/app.py", line 87, in security_middleware
NameError: name 'response' is not defined
2025-03-16 21:40:15,868 INFO: Inicio de la aplicación [in /Users/mcc/Documents/Develop/backup/sgha/backend/app.py:32]
2025-03-16 21:40:16,026 INFO: Permissions and roles initialized successfully. [in /Users/mcc/Documents/Develop/backup/sgha/backend/models/user.py:151]
2025-03-16 21:40:16,026 INFO: Permisos y roles inicializados correctamente [in /Users/mcc/Documents/Develop/backup/sgha/backend/app.py:58]
2025-03-16 22:08:30,740 INFO: Inicio de la aplicación [in /Users/mcc/Documents/Develop/backup/sgha/backend/app.py:32]
2025-03-16 22:08:30,882 INFO: Permissions and roles initialized successfully. [in /Users/mcc/Documents/Develop/backup/sgha/backend/models/user.py:151]
2025-03-16 22:08:30,882 INFO: Permisos y roles inicializados correctamente [in /Users/mcc/Documents/Develop/backup/sgha/backend/app.py:58]
2025-03-16 22:09:09,729 ERROR: Intento de acceso sin token [in /Users/mcc/Documents/Develop/backup/sgha/backend/app.py:124]
2025-03-16 22:09:13,091 ERROR: Intento de acceso sin token [in /Users/mcc/Documents/Develop/backup/sgha/backend/app.py:124]
2025-03-16 22:09:26,150 ERROR: Intento de acceso sin token [in /Users/mcc/Documents/Develop/backup/sgha/backend/app.py:124]
2025-03-16 22:09:26,205 ERROR: Intento de acceso sin token [in /Users/mcc/Documents/Develop/backup/sgha/backend/app.py:124]
2025-03-16 22:09:52,264 ERROR: Intento de acceso sin token [in /Users/mcc/Documents/Develop/backup/sgha/backend/app.py:124]
2025-03-16 22:10:07,119 ERROR: Intento de acceso sin token [in /Users/mcc/Documents/Develop/backup/sgha/backend/app.py:124]
2025-03-16 22:11:37,260 INFO: Inicio de la aplicación [in /Users/mcc/Documents/Develop/backup/sgha/backend/app.py:32]
2025-03-16 22:11:37,403 INFO: Permissions and roles initialized successfully. [in /Users/mcc/Documents/Develop/backup/sgha/backend/models/user.py:151]
2025-03-16 22:11:37,404 INFO: Permisos y roles inicializados correctamente [in /Users/mcc/Documents/Develop/backup/sgha/backend/app.py:58]
2025-03-16 22:13:06,324 ERROR: Intento de acceso sin token [in /Users/mcc/Documents/Develop/backup/sgha/backend/app.py:124]
2025-03-16 22:56:06,357 INFO: Inicio de la aplicación [in /Users/mcc/Documents/Develop/backup/sgha/backend/app.py:32]
2025-03-16 22:56:06,507 INFO: Permissions and roles initialized successfully. [in /Users/mcc/Documents/Develop/backup/sgha/backend/models/user.py:151]
2025-03-16 22:56:06,508 INFO: Permisos y roles inicializados correctamente [in /Users/mcc/Documents/Develop/backup/sgha/backend/app.py:58]
2025-03-16 23:00:38,594 INFO: Inicio de la aplicación [in /Users/mcc/Documents/Develop/backup/sgha/backend/app.py:32]
2025-03-16 23:00:38,748 INFO: Permissions and roles initialized successfully. [in /Users/mcc/Documents/Develop/backup/sgha/backend/models/user.py:151]
2025-03-16 23:00:38,748 INFO: Permisos y roles inicializados correctamente [in /Users/mcc/Documents/Develop/backup/sgha/backend/app.py:47]
2025-03-16 23:00:43,142 ERROR: Exception on /auth/login [POST] [in /Users/mcc/.virtualenvs/sgha/lib/python3.12/site-packages/flask/app.py:875]
Traceback (most recent call last):
  File "/Users/mcc/.virtualenvs/sgha/lib/python3.12/site-packages/flask/app.py", line 1511, in wsgi_app
    response = self.full_dispatch_request()
               ^^^^^^^^^^^^^^^^^^^^^^^^^^^^
  File "/Users/mcc/.virtualenvs/sgha/lib/python3.12/site-packages/flask/app.py", line 920, in full_dispatch_request
    return self.finalize_request(rv)
           ^^^^^^^^^^^^^^^^^^^^^^^^^
  File "/Users/mcc/.virtualenvs/sgha/lib/python3.12/site-packages/flask/app.py", line 941, in finalize_request
    response = self.process_response(response)
               ^^^^^^^^^^^^^^^^^^^^^^^^^^^^^^^
  File "/Users/mcc/.virtualenvs/sgha/lib/python3.12/site-packages/flask/app.py", line 1319, in process_response
    response = self.ensure_sync(func)(response)
               ^^^^^^^^^^^^^^^^^^^^^^^^^^^^^^^^
  File "/Users/mcc/Documents/Develop/backup/sgha/backend/app.py", line 78, in security_middleware
    response.headers['Access-Control-Allow-Origin'] = ', '.join(app.config['CORS_ORIGINS'])
                                                                ~~~~~~~~~~^^^^^^^^^^^^^^^^
KeyError: 'CORS_ORIGINS'
2025-03-16 23:00:43,146 ERROR: Request finalizing failed with an error while handling an error [in /Users/mcc/.virtualenvs/sgha/lib/python3.12/site-packages/flask/app.py:948]
Traceback (most recent call last):
  File "/Users/mcc/.virtualenvs/sgha/lib/python3.12/site-packages/flask/app.py", line 1511, in wsgi_app
    response = self.full_dispatch_request()
               ^^^^^^^^^^^^^^^^^^^^^^^^^^^^
  File "/Users/mcc/.virtualenvs/sgha/lib/python3.12/site-packages/flask/app.py", line 920, in full_dispatch_request
    return self.finalize_request(rv)
           ^^^^^^^^^^^^^^^^^^^^^^^^^
  File "/Users/mcc/.virtualenvs/sgha/lib/python3.12/site-packages/flask/app.py", line 941, in finalize_request
    response = self.process_response(response)
               ^^^^^^^^^^^^^^^^^^^^^^^^^^^^^^^
  File "/Users/mcc/.virtualenvs/sgha/lib/python3.12/site-packages/flask/app.py", line 1319, in process_response
    response = self.ensure_sync(func)(response)
               ^^^^^^^^^^^^^^^^^^^^^^^^^^^^^^^^
  File "/Users/mcc/Documents/Develop/backup/sgha/backend/app.py", line 78, in security_middleware
    response.headers['Access-Control-Allow-Origin'] = ', '.join(app.config['CORS_ORIGINS'])
                                                                ~~~~~~~~~~^^^^^^^^^^^^^^^^
KeyError: 'CORS_ORIGINS'

During handling of the above exception, another exception occurred:

Traceback (most recent call last):
  File "/Users/mcc/.virtualenvs/sgha/lib/python3.12/site-packages/flask/app.py", line 941, in finalize_request
    response = self.process_response(response)
               ^^^^^^^^^^^^^^^^^^^^^^^^^^^^^^^
  File "/Users/mcc/.virtualenvs/sgha/lib/python3.12/site-packages/flask/app.py", line 1319, in process_response
    response = self.ensure_sync(func)(response)
               ^^^^^^^^^^^^^^^^^^^^^^^^^^^^^^^^
  File "/Users/mcc/Documents/Develop/backup/sgha/backend/app.py", line 78, in security_middleware
    response.headers['Access-Control-Allow-Origin'] = ', '.join(app.config['CORS_ORIGINS'])
                                                                ~~~~~~~~~~^^^^^^^^^^^^^^^^
KeyError: 'CORS_ORIGINS'
