2025-03-17 16:05:55,214 INFO: Permissions and roles initialized successfully. [in /Users/mcc/Documents/Develop/backup/sgha/backend/models/user.py:151]
2025-03-17 16:05:55,215 INFO: Permisos y roles inicializados correctamente [in /Users/mcc/Documents/Develop/backup/sgha/backend/app.py:50]
2025-03-17 16:07:12,293 ERROR: Error de autenticación: 'JWTManager' object has no attribute 'decode_token' | ID: 56eeb665-e067-4877-8403-a4d11eea1507 [in /Users/mcc/Documents/Develop/backup/sgha/backend/app.py:138]
2025-03-17 16:07:16,916 ERROR: Error de autenticación: 'JWTManager' object has no attribute 'decode_token' | ID: 27b4dfee-81a0-4f15-b40c-c308265d1650 [in /Users/mcc/Documents/Develop/backup/sgha/backend/app.py:138]
2025-03-17 16:08:36,504 INFO: Inicio de la aplicación [in /Users/mcc/Documents/Develop/backup/sgha/backend/app.py:36]
2025-03-17 16:08:36,652 INFO: Permissions and roles initialized successfully. [in /Users/mcc/Documents/Develop/backup/sgha/backend/models/user.py:151]
2025-03-17 16:08:36,652 INFO: Permisos y roles inicializados correctamente [in /Users/mcc/Documents/Develop/backup/sgha/backend/app.py:50]
2025-03-17 16:08:41,796 ERROR: Error de autenticación: 'JWTManager' object has no attribute 'get_jwt' | ID: 917c99b0-8c05-434a-9239-b3aebb6d6063 [in /Users/mcc/Documents/Develop/backup/sgha/backend/app.py:138]
2025-03-17 16:15:58,995 ERROR: Error de autenticación: 'JWTManager' object has no attribute 'get_jwt' | ID: d817725e-21fc-43cd-af0c-08ed7e665c65 [in /Users/mcc/Documents/Develop/backup/sgha/backend/app.py:138]
2025-03-17 16:17:15,750 ERROR: Error de autenticación: 'JWTManager' object has no attribute 'get_jwt' | ID: e7b61c79-c4e6-4562-8dd2-607c0610ee65 [in /Users/mcc/Documents/Develop/backup/sgha/backend/app.py:138]
2025-03-17 16:21:58,659 INFO: Inicio de la aplicación [in /Users/mcc/Documents/Develop/backup/sgha/backend/app.py:36]
2025-03-17 16:21:58,801 INFO: Permissions and roles initialized successfully. [in /Users/mcc/Documents/Develop/backup/sgha/backend/models/user.py:151]
2025-03-17 16:21:58,801 INFO: Permisos y roles inicializados correctamente [in /Users/mcc/Documents/Develop/backup/sgha/backend/app.py:50]
2025-03-17 16:22:01,652 ERROR: Error de autenticación: 'JWTManager' object has no attribute 'get_jwt' | ID: a44c5acf-bd0f-4e23-bd3c-4567a143c0ac [in /Users/mcc/Documents/Develop/backup/sgha/backend/app.py:138]
2025-03-17 16:23:03,118 ERROR: Error de autenticación: 'JWTManager' object has no attribute 'get_jwt' | ID: f4f8d28d-86d4-4cf5-8fe8-ce1177454970 [in /Users/mcc/Documents/Develop/backup/sgha/backend/app.py:138]
2025-03-17 16:24:59,723 INFO: Inicio de la aplicación [in /Users/mcc/Documents/Develop/backup/sgha/backend/app.py:36]
2025-03-17 16:24:59,879 INFO: Permissions and roles initialized successfully. [in /Users/mcc/Documents/Develop/backup/sgha/backend/models/user.py:151]
2025-03-17 16:24:59,879 INFO: Permisos y roles inicializados correctamente [in /Users/mcc/Documents/Develop/backup/sgha/backend/app.py:50]
2025-03-17 16:45:37,107 ERROR: Error de autenticación: 'JWTManager' object has no attribute 'get_jwt' | ID: 26620961-9d85-427e-9223-dd528c3c2d1b [in /Users/mcc/Documents/Develop/backup/sgha/backend/app.py:138]
2025-03-17 16:51:54,632 ERROR: Error de autenticación: 'JWTManager' object has no attribute 'get_jwt' | ID: 388770c0-a932-426d-b8d2-5f138a4513fc [in /Users/mcc/Documents/Develop/backup/sgha/backend/app.py:138]
2025-03-17 17:05:14,100 INFO: Inicio de la aplicación [in /Users/mcc/Documents/Develop/backup/sgha/backend/app.py:36]
2025-03-17 17:05:14,265 INFO: Permissions and roles initialized successfully. [in /Users/mcc/Documents/Develop/backup/sgha/backend/models/user.py:151]
2025-03-17 17:05:14,265 INFO: Permisos y roles inicializados correctamente [in /Users/mcc/Documents/Develop/backup/sgha/backend/app.py:50]
2025-03-17 17:05:23,138 ERROR: Error de autenticación: 'JWTManager' object has no attribute 'get_jwt' | ID: bb99e8bc-5862-4c1c-a4b1-25660bff36ea [in /Users/mcc/Documents/Develop/backup/sgha/backend/app.py:138]
2025-03-17 17:22:22,688 INFO: Inicio de la aplicación [in /Users/mcc/Documents/Develop/backup/sgha/backend/app.py:37]
2025-03-17 17:22:22,833 INFO: Permissions and roles initialized successfully. [in /Users/mcc/Documents/Develop/backup/sgha/backend/models/user.py:151]
2025-03-17 17:22:22,834 INFO: Permisos y roles inicializados correctamente [in /Users/mcc/Documents/Develop/backup/sgha/backend/app.py:52]
2025-03-17 17:22:37,357 ERROR: Error de autenticación: 'JWTManager' object has no attribute 'get_jwt' | ID: 10d45c45-7689-4bb2-9550-7e5c34d62762 [in /Users/mcc/Documents/Develop/backup/sgha/backend/app.py:143]
2025-03-17 17:34:06,043 INFO: Inicio de la aplicación [in /Users/mcc/Documents/Develop/backup/sgha/backend/app.py:37]
2025-03-17 17:34:06,205 INFO: Permissions and roles initialized successfully. [in /Users/mcc/Documents/Develop/backup/sgha/backend/models/user.py:151]
2025-03-17 17:34:06,205 INFO: Permisos y roles inicializados correctamente [in /Users/mcc/Documents/Develop/backup/sgha/backend/app.py:52]
2025-03-17 17:34:17,213 ERROR: Exception on /auth/login [POST] [in /Users/mcc/.virtualenvs/sgha/lib/python3.12/site-packages/flask/app.py:875]
Traceback (most recent call last):
  File "/Users/mcc/.virtualenvs/sgha/lib/python3.12/site-packages/flask/app.py", line 1511, in wsgi_app
    response = self.full_dispatch_request()
               ^^^^^^^^^^^^^^^^^^^^^^^^^^^^
  File "/Users/mcc/.virtualenvs/sgha/lib/python3.12/site-packages/flask/app.py", line 919, in full_dispatch_request
    rv = self.handle_user_exception(e)
         ^^^^^^^^^^^^^^^^^^^^^^^^^^^^^
  File "/Users/mcc/.virtualenvs/sgha/lib/python3.12/site-packages/flask_cors/extension.py", line 176, in wrapped_function
    return cors_after_request(app.make_response(f(*args, **kwargs)))
                                                ^^^^^^^^^^^^^^^^^^
  File "/Users/mcc/.virtualenvs/sgha/lib/python3.12/site-packages/flask/app.py", line 917, in full_dispatch_request
    rv = self.dispatch_request()
         ^^^^^^^^^^^^^^^^^^^^^^^
  File "/Users/mcc/.virtualenvs/sgha/lib/python3.12/site-packages/flask/app.py", line 902, in dispatch_request
    return self.ensure_sync(self.view_functions[rule.endpoint])(**view_args)  # type: ignore[no-any-return]
           ^^^^^^^^^^^^^^^^^^^^^^^^^^^^^^^^^^^^^^^^^^^^^^^^^^^^^^^^^^^^^^^^^
  File "/Users/mcc/Documents/Develop/backup/sgha/backend/routes/auth.py", line 23, in login
    if not user or not check_password_hash(user.password, password):
                                           ^^^^^^^^^^^^^
AttributeError: 'User' object has no attribute 'password'
2025-03-17 17:40:07,403 ERROR: Exception on /auth/login [POST] [in /Users/mcc/.virtualenvs/sgha/lib/python3.12/site-packages/flask/app.py:875]
Traceback (most recent call last):
  File "/Users/mcc/.virtualenvs/sgha/lib/python3.12/site-packages/flask/app.py", line 1511, in wsgi_app
    response = self.full_dispatch_request()
               ^^^^^^^^^^^^^^^^^^^^^^^^^^^^
  File "/Users/mcc/.virtualenvs/sgha/lib/python3.12/site-packages/flask/app.py", line 919, in full_dispatch_request
    rv = self.handle_user_exception(e)
         ^^^^^^^^^^^^^^^^^^^^^^^^^^^^^
  File "/Users/mcc/.virtualenvs/sgha/lib/python3.12/site-packages/flask_cors/extension.py", line 176, in wrapped_function
    return cors_after_request(app.make_response(f(*args, **kwargs)))
                                                ^^^^^^^^^^^^^^^^^^
  File "/Users/mcc/.virtualenvs/sgha/lib/python3.12/site-packages/flask/app.py", line 917, in full_dispatch_request
    rv = self.dispatch_request()
         ^^^^^^^^^^^^^^^^^^^^^^^
  File "/Users/mcc/.virtualenvs/sgha/lib/python3.12/site-packages/flask/app.py", line 902, in dispatch_request
    return self.ensure_sync(self.view_functions[rule.endpoint])(**view_args)  # type: ignore[no-any-return]
           ^^^^^^^^^^^^^^^^^^^^^^^^^^^^^^^^^^^^^^^^^^^^^^^^^^^^^^^^^^^^^^^^^
  File "/Users/mcc/Documents/Develop/backup/sgha/backend/routes/auth.py", line 23, in login
    if not user or not check_password_hash(user.password_hash, password):
                                           ^^^^^^^^^^^^^
AttributeError: 'User' object has no attribute 'password'
2025-03-17 17:43:34,431 ERROR: Exception on /auth/login [POST] [in /Users/mcc/.virtualenvs/sgha/lib/python3.12/site-packages/flask/app.py:875]
Traceback (most recent call last):
  File "/Users/mcc/.virtualenvs/sgha/lib/python3.12/site-packages/flask/app.py", line 1511, in wsgi_app
    response = self.full_dispatch_request()
               ^^^^^^^^^^^^^^^^^^^^^^^^^^^^
  File "/Users/mcc/.virtualenvs/sgha/lib/python3.12/site-packages/flask/app.py", line 919, in full_dispatch_request
    rv = self.handle_user_exception(e)
         ^^^^^^^^^^^^^^^^^^^^^^^^^^^^^
  File "/Users/mcc/.virtualenvs/sgha/lib/python3.12/site-packages/flask_cors/extension.py", line 176, in wrapped_function
    return cors_after_request(app.make_response(f(*args, **kwargs)))
                                                ^^^^^^^^^^^^^^^^^^
  File "/Users/mcc/.virtualenvs/sgha/lib/python3.12/site-packages/flask/app.py", line 917, in full_dispatch_request
    rv = self.dispatch_request()
         ^^^^^^^^^^^^^^^^^^^^^^^
  File "/Users/mcc/.virtualenvs/sgha/lib/python3.12/site-packages/flask/app.py", line 902, in dispatch_request
    return self.ensure_sync(self.view_functions[rule.endpoint])(**view_args)  # type: ignore[no-any-return]
           ^^^^^^^^^^^^^^^^^^^^^^^^^^^^^^^^^^^^^^^^^^^^^^^^^^^^^^^^^^^^^^^^^
  File "/Users/mcc/Documents/Develop/backup/sgha/backend/routes/auth.py", line 23, in login
    "email": user.email,
                         
AttributeError: 'User' object has no attribute 'password'
