2025-03-17 17:43:36,219 ERROR: Exception on /auth/login [POST] [in /Users/mcc/.virtualenvs/sgha/lib/python3.12/site-packages/flask/app.py:875]
Traceback (most recent call last):
  File "/Users/mcc/.virtualenvs/sgha/lib/python3.12/site-packages/flask/app.py", line 1511, in wsgi_app
    response = self.full_dispatch_request()
               ^^^^^^^^^^^^^^^^^^^^^^^^^^^^
  File "/Users/mcc/.virtualenvs/sgha/lib/python3.12/site-packages/flask/app.py", line 919, in full_dispatch_request
    rv = self.handle_user_exception(e)
         ^^^^^^^^^^^^^^^^^^^^^^^^^^^^^
  File "/Users/mcc/.virtualenvs/sgha/lib/python3.12/site-packages/flask_cors/extension.py", line 176, in wrapped_function
    return cors_after_request(app.make_response(f(*args, **kwargs)))
                                                ^^^^^^^^^^^^^^^^^^
  File "/Users/mcc/.virtualenvs/sgha/lib/python3.12/site-packages/flask/app.py", line 917, in full_dispatch_request
    rv = self.dispatch_request()
         ^^^^^^^^^^^^^^^^^^^^^^^
  File "/Users/mcc/.virtualenvs/sgha/lib/python3.12/site-packages/flask/app.py", line 902, in dispatch_request
    return self.ensure_sync(self.view_functions[rule.endpoint])(**view_args)  # type: ignore[no-any-return]
           ^^^^^^^^^^^^^^^^^^^^^^^^^^^^^^^^^^^^^^^^^^^^^^^^^^^^^^^^^^^^^^^^^
  File "/Users/mcc/Documents/Develop/backup/sgha/backend/routes/auth.py", line 23, in login
    "email": user.email,
                         
AttributeError: 'User' object has no attribute 'password'
2025-03-17 17:45:30,910 INFO: Inicio de la aplicación [in /Users/mcc/Documents/Develop/backup/sgha/backend/app.py:37]
2025-03-17 17:45:31,073 INFO: Permissions and roles initialized successfully. [in /Users/mcc/Documents/Develop/backup/sgha/backend/models/user.py:151]
2025-03-17 17:45:31,074 INFO: Permisos y roles inicializados correctamente [in /Users/mcc/Documents/Develop/backup/sgha/backend/app.py:52]
2025-03-17 17:45:36,120 ERROR: Exception on /auth/login [POST] [in /Users/mcc/.virtualenvs/sgha/lib/python3.12/site-packages/flask/app.py:875]
Traceback (most recent call last):
  File "/Users/mcc/.virtualenvs/sgha/lib/python3.12/site-packages/flask/app.py", line 1511, in wsgi_app
    response = self.full_dispatch_request()
               ^^^^^^^^^^^^^^^^^^^^^^^^^^^^
  File "/Users/mcc/.virtualenvs/sgha/lib/python3.12/site-packages/flask/app.py", line 919, in full_dispatch_request
    rv = self.handle_user_exception(e)
         ^^^^^^^^^^^^^^^^^^^^^^^^^^^^^
  File "/Users/mcc/.virtualenvs/sgha/lib/python3.12/site-packages/flask_cors/extension.py", line 176, in wrapped_function
    return cors_after_request(app.make_response(f(*args, **kwargs)))
                                                ^^^^^^^^^^^^^^^^^^
  File "/Users/mcc/.virtualenvs/sgha/lib/python3.12/site-packages/flask/app.py", line 917, in full_dispatch_request
    rv = self.dispatch_request()
         ^^^^^^^^^^^^^^^^^^^^^^^
  File "/Users/mcc/.virtualenvs/sgha/lib/python3.12/site-packages/flask/app.py", line 902, in dispatch_request
    return self.ensure_sync(self.view_functions[rule.endpoint])(**view_args)  # type: ignore[no-any-return]
           ^^^^^^^^^^^^^^^^^^^^^^^^^^^^^^^^^^^^^^^^^^^^^^^^^^^^^^^^^^^^^^^^^
  File "/Users/mcc/Documents/Develop/backup/sgha/backend/routes/auth.py", line 23, in login
    if not user or not check_password_hash(user.password, password):
                                           ^^^^^^^^^^^^^
AttributeError: 'User' object has no attribute 'password'
2025-03-17 17:49:01,705 INFO: Inicio de la aplicación [in /Users/mcc/Documents/Develop/backup/sgha/backend/app.py:37]
2025-03-17 17:49:01,859 INFO: Permissions and roles initialized successfully. [in /Users/mcc/Documents/Develop/backup/sgha/backend/models/user.py:151]
2025-03-17 17:49:01,859 INFO: Permisos y roles inicializados correctamente [in /Users/mcc/Documents/Develop/backup/sgha/backend/app.py:52]
2025-03-17 17:50:04,628 ERROR: Error de autenticación: 'JWTManager' object has no attribute 'get_jwt' | ID: 54a68d72-8719-4a06-baea-d59e4531fda3 [in /Users/mcc/Documents/Develop/backup/sgha/backend/app.py:143]
2025-03-17 19:00:38,404 ERROR: Error de autenticación: 'JWTManager' object has no attribute 'get_jwt' | ID: 95542b80-d88c-46c7-bdd7-480812fdd280 [in /Users/mcc/Documents/Develop/backup/sgha/backend/app.py:143]
2025-03-17 19:03:06,243 ERROR: Intento de acceso sin token [in /Users/mcc/Documents/Develop/backup/sgha/backend/app.py:125]
2025-03-17 19:03:42,769 ERROR: Intento de acceso sin token [in /Users/mcc/Documents/Develop/backup/sgha/backend/app.py:125]
2025-03-17 19:47:17,634 INFO: Inicio de la aplicación [in /Users/mcc/Documents/Develop/backup/sgha/backend/app.py:37]
2025-03-17 19:47:17,798 INFO: Permissions and roles initialized successfully. [in /Users/mcc/Documents/Develop/backup/sgha/backend/models/user.py:151]
2025-03-17 19:47:17,799 INFO: Permisos y roles inicializados correctamente [in /Users/mcc/Documents/Develop/backup/sgha/backend/app.py:52]
2025-03-17 19:51:02,492 INFO: Inicio de la aplicación [in /Users/mcc/Documents/Develop/backup/sgha/backend/app.py:37]
2025-03-17 19:51:02,649 INFO: Permissions and roles initialized successfully. [in /Users/mcc/Documents/Develop/backup/sgha/backend/models/user.py:151]
2025-03-17 19:51:02,650 INFO: Permisos y roles inicializados correctamente [in /Users/mcc/Documents/Develop/backup/sgha/backend/app.py:52]
2025-03-17 19:51:08,994 ERROR: Error de autenticación: name 'verify_jwt_in_request' is not defined | ID: de1c84bf-4839-432d-8c97-61835c4a44d8 [in /Users/mcc/Documents/Develop/backup/sgha/backend/app.py:135]
2025-03-17 19:54:11,579 INFO: Inicio de la aplicación [in /Users/mcc/Documents/Develop/backup/sgha/backend/app.py:45]
2025-03-17 19:54:11,726 INFO: Permissions and roles initialized successfully. [in /Users/mcc/Documents/Develop/backup/sgha/backend/models/user.py:151]
2025-03-17 19:54:11,726 INFO: Permisos y roles inicializados correctamente [in /Users/mcc/Documents/Develop/backup/sgha/backend/app.py:60]
2025-03-17 19:54:41,619 ERROR: Error de autenticación: Subject must be a string | ID: 4e895089-415b-4ac0-9e2c-a6023f7c2fa3 [in /Users/mcc/Documents/Develop/backup/sgha/backend/app.py:143]
2025-03-17 20:01:08,515 INFO: Inicio de la aplicación [in /Users/mcc/Documents/Develop/backup/sgha/backend/app.py:45]
2025-03-17 20:01:08,673 INFO: Permissions and roles initialized successfully. [in /Users/mcc/Documents/Develop/backup/sgha/backend/models/user.py:151]
2025-03-17 20:01:08,673 INFO: Permisos y roles inicializados correctamente [in /Users/mcc/Documents/Develop/backup/sgha/backend/app.py:60]
2025-03-17 20:01:19,559 ERROR: Auth failed: Signature verification failed [in /Users/mcc/Documents/Develop/backup/sgha/backend/app.py:150]
2025-03-17 20:02:36,176 ERROR: Auth failed: Subject must be a string [in /Users/mcc/Documents/Develop/backup/sgha/backend/app.py:150]
2025-03-17 20:03:12,726 INFO: Inicio de la aplicación [in /Users/mcc/Documents/Develop/backup/sgha/backend/app.py:45]
2025-03-17 20:03:12,874 INFO: Permissions and roles initialized successfully. [in /Users/mcc/Documents/Develop/backup/sgha/backend/models/user.py:151]
2025-03-17 20:03:12,874 INFO: Permisos y roles inicializados correctamente [in /Users/mcc/Documents/Develop/backup/sgha/backend/app.py:60]
2025-03-17 20:03:45,602 ERROR: Auth failed: Signature verification failed [in /Users/mcc/Documents/Develop/backup/sgha/backend/app.py:150]
2025-03-17 20:29:30,657 INFO: Inicio de la aplicación [in /Users/mcc/Documents/Develop/backup/sgha/backend/app.py:45]
2025-03-17 20:29:30,805 INFO: Permissions and roles initialized successfully. [in /Users/mcc/Documents/Develop/backup/sgha/backend/models/user.py:151]
2025-03-17 20:29:30,805 INFO: Permisos y roles inicializados correctamente [in /Users/mcc/Documents/Develop/backup/sgha/backend/app.py:60]
2025-03-17 20:33:19,014 ERROR: Auth failed: Subject must be a string [in /Users/mcc/Documents/Develop/backup/sgha/backend/app.py:150]
2025-03-17 20:34:17,157 ERROR: Auth failed: Subject must be a string [in /Users/mcc/Documents/Develop/backup/sgha/backend/app.py:150]
2025-03-17 22:59:30,885 INFO: Inicio de la aplicación [in /Users/mcc/Documents/Develop/backup/sgha/backend/app.py:45]
2025-03-17 22:59:31,051 INFO: Permissions and roles initialized successfully. [in /Users/mcc/Documents/Develop/backup/sgha/backend/models/user.py:151]
2025-03-17 22:59:31,051 INFO: Permisos y roles inicializados correctamente [in /Users/mcc/Documents/Develop/backup/sgha/backend/app.py:60]
2025-03-17 23:13:37,387 ERROR: Auth failed: Signature verification failed [in /Users/mcc/Documents/Develop/backup/sgha/backend/app.py:150]
2025-03-17 23:13:37,397 ERROR: Auth failed: Signature verification failed [in /Users/mcc/Documents/Develop/backup/sgha/backend/app.py:150]
2025-03-17 23:13:39,374 ERROR: Auth failed: Subject must be a string [in /Users/mcc/Documents/Develop/backup/sgha/backend/app.py:150]
2025-03-17 23:13:39,382 ERROR: Auth failed: Subject must be a string [in /Users/mcc/Documents/Develop/backup/sgha/backend/app.py:150]
2025-03-18 00:13:03,313 ERROR: Auth failed: Subject must be a string [in /Users/mcc/Documents/Develop/backup/sgha/backend/app.py:150]
2025-03-18 00:13:03,318 ERROR: Auth failed: Subject must be a string [in /Users/mcc/Documents/Develop/backup/sgha/backend/app.py:150]
2025-03-18 01:30:14,285 ERROR: Auth failed: Subject must be a string [in /Users/mcc/Documents/Develop/backup/sgha/backend/app.py:150]
2025-03-18 01:33:42,076 ERROR: Auth failed: Subject must be a string [in /Users/mcc/Documents/Develop/backup/sgha/backend/app.py:150]
2025-03-18 01:33:51,546 ERROR: Auth failed: Subject must be a string [in /Users/mcc/Documents/Develop/backup/sgha/backend/app.py:150]
2025-03-18 01:37:30,731 ERROR: Auth failed: Subject must be a string [in /Users/mcc/Documents/Develop/backup/sgha/backend/app.py:150]
2025-03-18 01:38:13,457 ERROR: Auth failed: Subject must be a string [in /Users/mcc/Documents/Develop/backup/sgha/backend/app.py:150]
2025-03-18 01:40:18,278 ERROR: Auth failed: Subject must be a string [in /Users/mcc/Documents/Develop/backup/sgha/backend/app.py:150]
