2025-03-17 00:13:59,845 ERROR: Exception on /auth/login [OPTIONS] [in /Users/mcc/.virtualenvs/sgha/lib/python3.12/site-packages/flask/app.py:875]
Traceback (most recent call last):
  File "/Users/mcc/.virtualenvs/sgha/lib/python3.12/site-packages/flask/app.py", line 1511, in wsgi_app
    response = self.full_dispatch_request()
               ^^^^^^^^^^^^^^^^^^^^^^^^^^^^
  File "/Users/mcc/.virtualenvs/sgha/lib/python3.12/site-packages/flask/app.py", line 920, in full_dispatch_request
    return self.finalize_request(rv)
           ^^^^^^^^^^^^^^^^^^^^^^^^^
  File "/Users/mcc/.virtualenvs/sgha/lib/python3.12/site-packages/flask/app.py", line 941, in finalize_request
    response = self.process_response(response)
               ^^^^^^^^^^^^^^^^^^^^^^^^^^^^^^^
  File "/Users/mcc/.virtualenvs/sgha/lib/python3.12/site-packages/flask/app.py", line 1319, in process_response
    response = self.ensure_sync(func)(response)
               ^^^^^^^^^^^^^^^^^^^^^^^^^^^^^^^^
  File "/Users/mcc/Documents/Develop/backup/sgha/backend/app.py", line 78, in security_middleware
    response.headers['Content-Security-Policy'] = "default-src 'self'"
                                                                ^^^^^^^
KeyError: 'CORS_ORIGINS'
2025-03-17 00:13:59,847 ERROR: Request finalizing failed with an error while handling an error [in /Users/mcc/.virtualenvs/sgha/lib/python3.12/site-packages/flask/app.py:948]
Traceback (most recent call last):
  File "/Users/mcc/.virtualenvs/sgha/lib/python3.12/site-packages/flask/app.py", line 1511, in wsgi_app
    response = self.full_dispatch_request()
               ^^^^^^^^^^^^^^^^^^^^^^^^^^^^
  File "/Users/mcc/.virtualenvs/sgha/lib/python3.12/site-packages/flask/app.py", line 920, in full_dispatch_request
    return self.finalize_request(rv)
           ^^^^^^^^^^^^^^^^^^^^^^^^^
  File "/Users/mcc/.virtualenvs/sgha/lib/python3.12/site-packages/flask/app.py", line 941, in finalize_request
    response = self.process_response(response)
               ^^^^^^^^^^^^^^^^^^^^^^^^^^^^^^^
  File "/Users/mcc/.virtualenvs/sgha/lib/python3.12/site-packages/flask/app.py", line 1319, in process_response
    response = self.ensure_sync(func)(response)
               ^^^^^^^^^^^^^^^^^^^^^^^^^^^^^^^^
  File "/Users/mcc/Documents/Develop/backup/sgha/backend/app.py", line 78, in security_middleware
    response.headers['Content-Security-Policy'] = "default-src 'self'"
                                                                ^^^^^^^
KeyError: 'CORS_ORIGINS'

During handling of the above exception, another exception occurred:

Traceback (most recent call last):
  File "/Users/mcc/.virtualenvs/sgha/lib/python3.12/site-packages/flask/app.py", line 941, in finalize_request
    response = self.process_response(response)
               ^^^^^^^^^^^^^^^^^^^^^^^^^^^^^^^
  File "/Users/mcc/.virtualenvs/sgha/lib/python3.12/site-packages/flask/app.py", line 1319, in process_response
    response = self.ensure_sync(func)(response)
               ^^^^^^^^^^^^^^^^^^^^^^^^^^^^^^^^
  File "/Users/mcc/Documents/Develop/backup/sgha/backend/app.py", line 78, in security_middleware
    response.headers['Content-Security-Policy'] = "default-src 'self'"
                                                                ^^^^^^^
KeyError: 'CORS_ORIGINS'
2025-03-17 14:38:23,444 ERROR: Exception on /auth/login [POST] [in /Users/mcc/.virtualenvs/sgha/lib/python3.12/site-packages/flask/app.py:875]
Traceback (most recent call last):
  File "/Users/mcc/.virtualenvs/sgha/lib/python3.12/site-packages/flask/app.py", line 1511, in wsgi_app
    response = self.full_dispatch_request()
               ^^^^^^^^^^^^^^^^^^^^^^^^^^^^
  File "/Users/mcc/.virtualenvs/sgha/lib/python3.12/site-packages/flask/app.py", line 920, in full_dispatch_request
    return self.finalize_request(rv)
           ^^^^^^^^^^^^^^^^^^^^^^^^^
  File "/Users/mcc/.virtualenvs/sgha/lib/python3.12/site-packages/flask/app.py", line 941, in finalize_request
    response = self.process_response(response)
               ^^^^^^^^^^^^^^^^^^^^^^^^^^^^^^^
  File "/Users/mcc/.virtualenvs/sgha/lib/python3.12/site-packages/flask/app.py", line 1319, in process_response
    response = self.ensure_sync(func)(response)
               ^^^^^^^^^^^^^^^^^^^^^^^^^^^^^^^^
  File "/Users/mcc/Documents/Develop/backup/sgha/backend/app.py", line 78, in security_middleware
    response.headers['Content-Security-Policy'] = "default-src 'self'"
                                                                ^^^^^^^
KeyError: 'CORS_ORIGINS'
2025-03-17 14:38:23,522 ERROR: Request finalizing failed with an error while handling an error [in /Users/mcc/.virtualenvs/sgha/lib/python3.12/site-packages/flask/app.py:948]
Traceback (most recent call last):
  File "/Users/mcc/.virtualenvs/sgha/lib/python3.12/site-packages/flask/app.py", line 1511, in wsgi_app
    response = self.full_dispatch_request()
               ^^^^^^^^^^^^^^^^^^^^^^^^^^^^
  File "/Users/mcc/.virtualenvs/sgha/lib/python3.12/site-packages/flask/app.py", line 920, in full_dispatch_request
    return self.finalize_request(rv)
           ^^^^^^^^^^^^^^^^^^^^^^^^^
  File "/Users/mcc/.virtualenvs/sgha/lib/python3.12/site-packages/flask/app.py", line 941, in finalize_request
    response = self.process_response(response)
               ^^^^^^^^^^^^^^^^^^^^^^^^^^^^^^^
  File "/Users/mcc/.virtualenvs/sgha/lib/python3.12/site-packages/flask/app.py", line 1319, in process_response
    response = self.ensure_sync(func)(response)
               ^^^^^^^^^^^^^^^^^^^^^^^^^^^^^^^^
  File "/Users/mcc/Documents/Develop/backup/sgha/backend/app.py", line 78, in security_middleware
    response.headers['Content-Security-Policy'] = "default-src 'self'"
                                                                ^^^^^^^
KeyError: 'CORS_ORIGINS'

During handling of the above exception, another exception occurred:

Traceback (most recent call last):
  File "/Users/mcc/.virtualenvs/sgha/lib/python3.12/site-packages/flask/app.py", line 941, in finalize_request
    response = self.process_response(response)
               ^^^^^^^^^^^^^^^^^^^^^^^^^^^^^^^
  File "/Users/mcc/.virtualenvs/sgha/lib/python3.12/site-packages/flask/app.py", line 1319, in process_response
    response = self.ensure_sync(func)(response)
               ^^^^^^^^^^^^^^^^^^^^^^^^^^^^^^^^
  File "/Users/mcc/Documents/Develop/backup/sgha/backend/app.py", line 78, in security_middleware
    response.headers['Content-Security-Policy'] = "default-src 'self'"
                                                                ^^^^^^^
KeyError: 'CORS_ORIGINS'
2025-03-17 14:39:29,306 INFO: Inicio de la aplicaci√≥n [in /Users/mcc/Documents/Develop/backup/sgha/backend/app.py:35]
2025-03-17 14:39:29,560 INFO: Permissions and roles initialized successfully. [in /Users/mcc/Documents/Develop/backup/sgha/backend/models/user.py:151]
2025-03-17 14:39:29,560 INFO: Permisos y roles inicializados correctamente [in /Users/mcc/Documents/Develop/backup/sgha/backend/app.py:50]
2025-03-17 14:39:36,549 ERROR: Exception on /auth/login [POST] [in /Users/mcc/.virtualenvs/sgha/lib/python3.12/site-packages/flask/app.py:875]
Traceback (most recent call last):
  File "/Users/mcc/.virtualenvs/sgha/lib/python3.12/site-packages/flask/app.py", line 1511, in wsgi_app
    response = self.full_dispatch_request()
               ^^^^^^^^^^^^^^^^^^^^^^^^^^^^
  File "/Users/mcc/.virtualenvs/sgha/lib/python3.12/site-packages/flask/app.py", line 920, in full_dispatch_request
    return self.finalize_request(rv)
           ^^^^^^^^^^^^^^^^^^^^^^^^^
  File "/Users/mcc/.virtualenvs/sgha/lib/python3.12/site-packages/flask/app.py", line 941, in finalize_request
    response = self.process_response(response)
               ^^^^^^^^^^^^^^^^^^^^^^^^^^^^^^^
  File "/Users/mcc/.virtualenvs/sgha/lib/python3.12/site-packages/flask/app.py", line 1319, in process_response
    response = self.ensure_sync(func)(response)
               ^^^^^^^^^^^^^^^^^^^^^^^^^^^^^^^^
  File "/Users/mcc/Documents/Develop/backup/sgha/backend/app.py", line 76, in security_middleware
    response.headers['X-Content-Type-Options'] = 'nosniff'
    ^^^^^^^^^^^^^^^^
AttributeError: 'NoneType' object has no attribute 'headers'
2025-03-17 14:39:36,554 ERROR: Request finalizing failed with an error while handling an error [in /Users/mcc/.virtualenvs/sgha/lib/python3.12/site-packages/flask/app.py:948]
Traceback (most recent call last):
  File "/Users/mcc/.virtualenvs/sgha/lib/python3.12/site-packages/flask/app.py", line 1511, in wsgi_app
    response = self.full_dispatch_request()
               ^^^^^^^^^^^^^^^^^^^^^^^^^^^^
  File "/Users/mcc/.virtualenvs/sgha/lib/python3.12/site-packages/flask/app.py", line 920, in full_dispatch_request
    return self.finalize_request(rv)
           ^^^^^^^^^^^^^^^^^^^^^^^^^
  File "/Users/mcc/.virtualenvs/sgha/lib/python3.12/site-packages/flask/app.py", line 941, in finalize_request
    response = self.process_response(response)
               ^^^^^^^^^^^^^^^^^^^^^^^^^^^^^^^
  File "/Users/mcc/.virtualenvs/sgha/lib/python3.12/site-packages/flask/app.py", line 1319, in process_response
    response = self.ensure_sync(func)(response)
               ^^^^^^^^^^^^^^^^^^^^^^^^^^^^^^^^
  File "/Users/mcc/Documents/Develop/backup/sgha/backend/app.py", line 76, in security_middleware
    response.headers['X-Content-Type-Options'] = 'nosniff'
    ^^^^^^^^^^^^^^^^
AttributeError: 'NoneType' object has no attribute 'headers'

During handling of the above exception, another exception occurred:

Traceback (most recent call last):
  File "/Users/mcc/.virtualenvs/sgha/lib/python3.12/site-packages/flask/app.py", line 941, in finalize_request
    response = self.process_response(response)
               ^^^^^^^^^^^^^^^^^^^^^^^^^^^^^^^
  File "/Users/mcc/.virtualenvs/sgha/lib/python3.12/site-packages/flask/app.py", line 1319, in process_response
    response = self.ensure_sync(func)(response)
               ^^^^^^^^^^^^^^^^^^^^^^^^^^^^^^^^
  File "/Users/mcc/Documents/Develop/backup/sgha/backend/app.py", line 76, in security_middleware
    response.headers['X-Content-Type-Options'] = 'nosniff'
    ^^^^^^^^^^^^^^^^
AttributeError: 'NoneType' object has no attribute 'headers'
