2025-03-17 14:39:40,570 ERROR: Exception on /auth/login [POST] [in /Users/mcc/.virtualenvs/sgha/lib/python3.12/site-packages/flask/app.py:875]
Traceback (most recent call last):
  File "/Users/mcc/.virtualenvs/sgha/lib/python3.12/site-packages/flask/app.py", line 1511, in wsgi_app
    response = self.full_dispatch_request()
               ^^^^^^^^^^^^^^^^^^^^^^^^^^^^
  File "/Users/mcc/.virtualenvs/sgha/lib/python3.12/site-packages/flask/app.py", line 920, in full_dispatch_request
    return self.finalize_request(rv)
           ^^^^^^^^^^^^^^^^^^^^^^^^^
  File "/Users/mcc/.virtualenvs/sgha/lib/python3.12/site-packages/flask/app.py", line 941, in finalize_request
    response = self.process_response(response)
               ^^^^^^^^^^^^^^^^^^^^^^^^^^^^^^^
  File "/Users/mcc/.virtualenvs/sgha/lib/python3.12/site-packages/flask/app.py", line 1319, in process_response
    response = self.ensure_sync(func)(response)
               ^^^^^^^^^^^^^^^^^^^^^^^^^^^^^^^^
  File "/Users/mcc/Documents/Develop/backup/sgha/backend/app.py", line 76, in security_middleware
    response.headers['X-Content-Type-Options'] = 'nosniff'
    ^^^^^^^^^^^^^^^^
AttributeError: 'NoneType' object has no attribute 'headers'
2025-03-17 14:39:40,575 ERROR: Request finalizing failed with an error while handling an error [in /Users/mcc/.virtualenvs/sgha/lib/python3.12/site-packages/flask/app.py:948]
Traceback (most recent call last):
  File "/Users/mcc/.virtualenvs/sgha/lib/python3.12/site-packages/flask/app.py", line 1511, in wsgi_app
    response = self.full_dispatch_request()
               ^^^^^^^^^^^^^^^^^^^^^^^^^^^^
  File "/Users/mcc/.virtualenvs/sgha/lib/python3.12/site-packages/flask/app.py", line 920, in full_dispatch_request
    return self.finalize_request(rv)
           ^^^^^^^^^^^^^^^^^^^^^^^^^
  File "/Users/mcc/.virtualenvs/sgha/lib/python3.12/site-packages/flask/app.py", line 941, in finalize_request
    response = self.process_response(response)
               ^^^^^^^^^^^^^^^^^^^^^^^^^^^^^^^
  File "/Users/mcc/.virtualenvs/sgha/lib/python3.12/site-packages/flask/app.py", line 1319, in process_response
    response = self.ensure_sync(func)(response)
               ^^^^^^^^^^^^^^^^^^^^^^^^^^^^^^^^
  File "/Users/mcc/Documents/Develop/backup/sgha/backend/app.py", line 76, in security_middleware
    response.headers['X-Content-Type-Options'] = 'nosniff'
    ^^^^^^^^^^^^^^^^
AttributeError: 'NoneType' object has no attribute 'headers'

During handling of the above exception, another exception occurred:

Traceback (most recent call last):
  File "/Users/mcc/.virtualenvs/sgha/lib/python3.12/site-packages/flask/app.py", line 941, in finalize_request
    response = self.process_response(response)
               ^^^^^^^^^^^^^^^^^^^^^^^^^^^^^^^
  File "/Users/mcc/.virtualenvs/sgha/lib/python3.12/site-packages/flask/app.py", line 1319, in process_response
    response = self.ensure_sync(func)(response)
               ^^^^^^^^^^^^^^^^^^^^^^^^^^^^^^^^
  File "/Users/mcc/Documents/Develop/backup/sgha/backend/app.py", line 76, in security_middleware
    response.headers['X-Content-Type-Options'] = 'nosniff'
    ^^^^^^^^^^^^^^^^
AttributeError: 'NoneType' object has no attribute 'headers'
2025-03-17 15:02:55,723 INFO: Inicio de la aplicación [in /Users/mcc/Documents/Develop/backup/sgha/backend/app.py:35]
2025-03-17 15:02:56,170 INFO: Permissions and roles initialized successfully. [in /Users/mcc/Documents/Develop/backup/sgha/backend/models/user.py:151]
2025-03-17 15:02:56,171 INFO: Permisos y roles inicializados correctamente [in /Users/mcc/Documents/Develop/backup/sgha/backend/app.py:50]
2025-03-17 15:03:43,238 INFO: Inicio de la aplicación [in /Users/mcc/Documents/Develop/backup/sgha/backend/app.py:35]
2025-03-17 15:03:43,368 INFO: Permissions and roles initialized successfully. [in /Users/mcc/Documents/Develop/backup/sgha/backend/models/user.py:151]
2025-03-17 15:03:43,368 INFO: Permisos y roles inicializados correctamente [in /Users/mcc/Documents/Develop/backup/sgha/backend/app.py:50]
2025-03-17 15:08:10,605 INFO: Inicio de la aplicación [in /Users/mcc/Documents/Develop/backup/sgha/backend/app.py:35]
2025-03-17 15:08:10,739 INFO: Permissions and roles initialized successfully. [in /Users/mcc/Documents/Develop/backup/sgha/backend/models/user.py:151]
2025-03-17 15:08:10,739 INFO: Permisos y roles inicializados correctamente [in /Users/mcc/Documents/Develop/backup/sgha/backend/app.py:50]
2025-03-17 15:08:17,007 ERROR: Intento de acceso sin token [in /Users/mcc/Documents/Develop/backup/sgha/backend/app.py:120]
